Traceback (most recent call last):
  File "D:\MisTrabajos\Pytorch\pytorch\lib\site-packages\jupyter_cache\executors\utils.py", line 58, in single_nb_execution
    executenb(
  File "D:\MisTrabajos\Pytorch\pytorch\lib\site-packages\nbclient\client.py", line 1305, in execute
    return NotebookClient(nb=nb, resources=resources, km=km, **kwargs).execute()
  File "D:\MisTrabajos\Pytorch\pytorch\lib\site-packages\jupyter_core\utils\__init__.py", line 166, in wrapped
    return loop.run_until_complete(inner)
  File "D:\programas\Anaconda\envs\py310\lib\asyncio\base_events.py", line 649, in run_until_complete
    return future.result()
  File "D:\MisTrabajos\Pytorch\pytorch\lib\site-packages\nbclient\client.py", line 705, in async_execute
    await self.async_execute_cell(
  File "D:\MisTrabajos\Pytorch\pytorch\lib\site-packages\nbclient\client.py", line 1058, in async_execute_cell
    await self._check_raise_for_error(cell, cell_index, exec_reply)
  File "D:\MisTrabajos\Pytorch\pytorch\lib\site-packages\nbclient\client.py", line 914, in _check_raise_for_error
    raise CellExecutionError.from_cell_and_msg(cell, exec_reply_content)
nbclient.exceptions.CellExecutionError: An error occurred while executing the following cell:
------------------
classes = (predictions >= 0).astype(np.int)
classes
------------------


[1;31m---------------------------------------------------------------------------[0m
[1;31mAttributeError[0m                            Traceback (most recent call last)
Cell [1;32mIn[36], line 1[0m
[1;32m----> 1[0m classes [38;5;241m=[39m (predictions [38;5;241m>[39m[38;5;241m=[39m [38;5;241m0[39m)[38;5;241m.[39mastype([43mnp[49m[38;5;241;43m.[39;49m[43mint[49m)
[0;32m      2[0m classes

File [1;32mD:\MisTrabajos\Pytorch\pytorch\lib\site-packages\numpy\__init__.py:284[0m, in [0;36m__getattr__[1;34m(attr)[0m
[0;32m    281[0m     [38;5;28;01mfrom[39;00m [38;5;21;01m.[39;00m[38;5;21;01mtesting[39;00m [38;5;28;01mimport[39;00m Tester
[0;32m    282[0m     [38;5;28;01mreturn[39;00m Tester
[1;32m--> 284[0m [38;5;28;01mraise[39;00m [38;5;167;01mAttributeError[39;00m([38;5;124m"[39m[38;5;124mmodule [39m[38;5;132;01m{!r}[39;00m[38;5;124m has no attribute [39m[38;5;124m"[39m
[0;32m    285[0m                      [38;5;124m"[39m[38;5;132;01m{!r}[39;00m[38;5;124m"[39m[38;5;241m.[39mformat([38;5;18m__name__[39m, attr))

[1;31mAttributeError[0m: module 'numpy' has no attribute 'int'

