Traceback (most recent call last):
  File "D:\MisTrabajos\Pytorch\pytorch\lib\site-packages\jupyter_cache\executors\utils.py", line 58, in single_nb_execution
    executenb(
  File "D:\MisTrabajos\Pytorch\pytorch\lib\site-packages\nbclient\client.py", line 1305, in execute
    return NotebookClient(nb=nb, resources=resources, km=km, **kwargs).execute()
  File "D:\MisTrabajos\Pytorch\pytorch\lib\site-packages\jupyter_core\utils\__init__.py", line 166, in wrapped
    return loop.run_until_complete(inner)
  File "D:\programas\Anaconda\envs\py310\lib\asyncio\base_events.py", line 649, in run_until_complete
    return future.result()
  File "D:\MisTrabajos\Pytorch\pytorch\lib\site-packages\nbclient\client.py", line 705, in async_execute
    await self.async_execute_cell(
  File "D:\MisTrabajos\Pytorch\pytorch\lib\site-packages\nbclient\client.py", line 1058, in async_execute_cell
    await self._check_raise_for_error(cell, cell_index, exec_reply)
  File "D:\MisTrabajos\Pytorch\pytorch\lib\site-packages\nbclient\client.py", line 914, in _check_raise_for_error
    raise CellExecutionError.from_cell_and_msg(cell, exec_reply_content)
nbclient.exceptions.CellExecutionError: An error occurred while executing the following cell:
------------------
writer.add_graph(model)
------------------

----- stdout -----
example_kwarg_inputs should be a dict
Error occurs, No graph saved
------------------

[1;31m---------------------------------------------------------------------------[0m
[1;31mRuntimeError[0m                              Traceback (most recent call last)
Cell [1;32mIn[51], line 1[0m
[1;32m----> 1[0m [43mwriter[49m[38;5;241;43m.[39;49m[43madd_graph[49m[43m([49m[43mmodel[49m[43m)[49m

File [1;32mD:\MisTrabajos\Pytorch\pytorch\lib\site-packages\torch\utils\tensorboard\writer.py:841[0m, in [0;36mSummaryWriter.add_graph[1;34m(self, model, input_to_model, verbose, use_strict_trace)[0m
[0;32m    837[0m torch[38;5;241m.[39m_C[38;5;241m.[39m_log_api_usage_once([38;5;124m"[39m[38;5;124mtensorboard.logging.add_graph[39m[38;5;124m"[39m)
[0;32m    838[0m [38;5;28;01mif[39;00m [38;5;28mhasattr[39m(model, [38;5;124m"[39m[38;5;124mforward[39m[38;5;124m"[39m):
[0;32m    839[0m     [38;5;66;03m# A valid PyTorch model should have a 'forward' method[39;00m
[0;32m    840[0m     [38;5;28mself[39m[38;5;241m.[39m_get_file_writer()[38;5;241m.[39madd_graph(
[1;32m--> 841[0m         [43mgraph[49m[43m([49m[43mmodel[49m[43m,[49m[43m [49m[43minput_to_model[49m[43m,[49m[43m [49m[43mverbose[49m[43m,[49m[43m [49m[43muse_strict_trace[49m[43m)[49m
[0;32m    842[0m     )
[0;32m    843[0m [38;5;28;01melse[39;00m:
[0;32m    844[0m     [38;5;66;03m# Caffe2 models do not have the 'forward' method[39;00m
[0;32m    845[0m     [38;5;28;01mfrom[39;00m [38;5;21;01mcaffe2[39;00m[38;5;21;01m.[39;00m[38;5;21;01mproto[39;00m [38;5;28;01mimport[39;00m caffe2_pb2

File [1;32mD:\MisTrabajos\Pytorch\pytorch\lib\site-packages\torch\utils\tensorboard\_pytorch_graph.py:343[0m, in [0;36mgraph[1;34m(model, args, verbose, use_strict_trace)[0m
[0;32m    341[0m         [38;5;28mprint[39m(e)
[0;32m    342[0m         [38;5;28mprint[39m([38;5;124m"[39m[38;5;124mError occurs, No graph saved[39m[38;5;124m"[39m)
[1;32m--> 343[0m         [38;5;28;01mraise[39;00m e
[0;32m    345[0m [38;5;28;01mif[39;00m verbose:
[0;32m    346[0m     [38;5;28mprint[39m(graph)

File [1;32mD:\MisTrabajos\Pytorch\pytorch\lib\site-packages\torch\utils\tensorboard\_pytorch_graph.py:337[0m, in [0;36mgraph[1;34m(model, args, verbose, use_strict_trace)[0m
[0;32m    335[0m [38;5;28;01mwith[39;00m _set_model_to_eval(model):
[0;32m    336[0m     [38;5;28;01mtry[39;00m:
[1;32m--> 337[0m         trace [38;5;241m=[39m [43mtorch[49m[38;5;241;43m.[39;49m[43mjit[49m[38;5;241;43m.[39;49m[43mtrace[49m[43m([49m[43mmodel[49m[43m,[49m[43m [49m[43margs[49m[43m,[49m[43m [49m[43mstrict[49m[38;5;241;43m=[39;49m[43muse_strict_trace[49m[43m)[49m
[0;32m    338[0m         graph [38;5;241m=[39m trace[38;5;241m.[39mgraph
[0;32m    339[0m         torch[38;5;241m.[39m_C[38;5;241m.[39m_jit_pass_inline(graph)

File [1;32mD:\MisTrabajos\Pytorch\pytorch\lib\site-packages\torch\jit\_trace.py:793[0m, in [0;36mtrace[1;34m(func, example_inputs, optimize, check_trace, check_inputs, check_tolerance, strict, _force_outplace, _module_class, _compilation_unit, example_kwarg_inputs, _store_inputs)[0m
[0;32m    791[0m             example_inputs [38;5;241m=[39m example_kwarg_inputs
[0;32m    792[0m         [38;5;28;01melse[39;00m:
[1;32m--> 793[0m             [38;5;28;01mraise[39;00m [38;5;167;01mRuntimeError[39;00m([38;5;124m"[39m[38;5;124mexample_kwarg_inputs should be a dict[39m[38;5;124m"[39m)
[0;32m    794[0m     [38;5;28;01mreturn[39;00m trace_module(
[0;32m    795[0m         func,
[0;32m    796[0m         {[38;5;124m"[39m[38;5;124mforward[39m[38;5;124m"[39m: example_inputs},
[1;32m   (...)[0m
[0;32m    805[0m         _store_inputs[38;5;241m=[39m_store_inputs
[0;32m    806[0m     )
[0;32m    807[0m [38;5;28;01mif[39;00m (
[0;32m    808[0m     [38;5;28mhasattr[39m(func, [38;5;124m"[39m[38;5;124m__self__[39m[38;5;124m"[39m)
[0;32m    809[0m     [38;5;129;01mand[39;00m [38;5;28misinstance[39m(func[38;5;241m.[39m[38;5;18m__self__[39m, torch[38;5;241m.[39mnn[38;5;241m.[39mModule)
[0;32m    810[0m     [38;5;129;01mand[39;00m func[38;5;241m.[39m[38;5;18m__name__[39m [38;5;241m==[39m [38;5;124m"[39m[38;5;124mforward[39m[38;5;124m"[39m
[0;32m    811[0m ):

[1;31mRuntimeError[0m: example_kwarg_inputs should be a dict

