Traceback (most recent call last):
  File "D:\programas\Anaconda\envs\py39\lib\site-packages\jupyter_cache\executors\utils.py", line 51, in single_nb_execution
    executenb(
  File "D:\programas\Anaconda\envs\py39\lib\site-packages\nbclient\client.py", line 1204, in execute
    return NotebookClient(nb=nb, resources=resources, km=km, **kwargs).execute()
  File "D:\programas\Anaconda\envs\py39\lib\site-packages\nbclient\util.py", line 84, in wrapped
    return just_run(coro(*args, **kwargs))
  File "D:\programas\Anaconda\envs\py39\lib\site-packages\nbclient\util.py", line 62, in just_run
    return loop.run_until_complete(coro)
  File "D:\programas\Anaconda\envs\py39\lib\asyncio\base_events.py", line 647, in run_until_complete
    return future.result()
  File "D:\programas\Anaconda\envs\py39\lib\site-packages\nbclient\client.py", line 663, in async_execute
    await self.async_execute_cell(
  File "D:\programas\Anaconda\envs\py39\lib\site-packages\nbclient\client.py", line 965, in async_execute_cell
    await self._check_raise_for_error(cell, cell_index, exec_reply)
  File "D:\programas\Anaconda\envs\py39\lib\site-packages\nbclient\client.py", line 862, in _check_raise_for_error
    raise CellExecutionError.from_cell_and_msg(cell, exec_reply_content)
nbclient.exceptions.CellExecutionError: An error occurred while executing the following cell:
------------------
last_horizontal_region * identity
------------------

[1;31m---------------------------------------------------------------------------[0m
[1;31mValueError[0m                                Traceback (most recent call last)
Input [1;32mIn [9][0m, in [0;36m<cell line: 1>[1;34m()[0m
[1;32m----> 1[0m [43mlast_horizontal_region[49m[43m [49m[38;5;241;43m*[39;49m[43m [49m[43midentity[49m

[1;31mValueError[0m: operands could not be broadcast together with shapes (1,1,3,2) (1,1,3,3) 
ValueError: operands could not be broadcast together with shapes (1,1,3,2) (1,1,3,3) 

